<?xml version="1.0"?>
<robot xmlns:xacro="http://www.ros.org/wiki/xacro" >

    <material name="white">
        <color rgba="1 1 1 1" />
    </material>

    <material name="orange">
        <color rgba="1 0.3 0.1 1"/>
    </material>

    <material name="blue">
        <color rgba="0.2 0.2 1 1"/>
    </material>

    <material name="black">
        <color rgba="0 0 0 1"/>
    </material>

    <link name="base_link">

    </link>

    <joint name="chassis_joint" type="fixed">
        <parent link= "base_link"/>
        <child link= "chassis" />
        <origin xyz="-0.08 0 0" />
    </joint>

    <link name="chassis">
        <visual>
        <origin xyz="0.1 0 0.045"/>
            <geometry>
                <box size="0.2 0.11 0.1"/>
            </geometry> 
            <material name="white"/> 
       </visual>
    </link>   

    <!--Left-Front Wheel-->
    <joint name="left_front_wheel_joint" type="continuous">
        <parent link="base_link"/>
        <child link="left_front_wheel"/>
        <origin xyz="0.047 0.065 0" rpy="-${pi/2} 0 0"/>
        <axis xyz="0 0 1"/>
    </joint>

    <link name="left_front_wheel">
        <visual>
            <origin xyz="0 0 0" rpy="0 0 0"/>
            <geometry>
                <cylinder length="0.02" radius="0.0235"/>
            </geometry>
            <material name="black"/>
        </visual>
    </link>

    <!--Right-Front Wheel-->
    <joint name="right_front_wheel_joint" type="continuous">
        <parent link="base_link"/>
        <child link="right_front_wheel"/>
        <origin xyz="0.047 -0.065 0" rpy="${pi/2} 0 0"/>
        <axis xyz="0 0 -1"/>
    </joint>

    <link name="right_front_wheel">
        <visual>
            <origin xyz="0 0 0" rpy="0 0 0"/>
            <geometry>
                <cylinder length="0.02" radius="0.0235"/>
            </geometry>
            <material name="black"/>
        </visual>
    </link>

    <!--Left-Back Wheel-->
    <joint name="left_back_wheel_joint" type="continuous">
        <parent link="base_link"/>
        <child link="left_back_wheel"/>
        <origin xyz="-0.047 0.065 0" rpy="-${pi/2} 0 0"/>
        <axis xyz="0 0 1"/>
    </joint>

    <link name="left_back_wheel">
        <visual>
            <origin xyz="0 0 0" rpy="0 0 0"/>
            <geometry>
                <cylinder length="0.02" radius="0.0235"/>
            </geometry>
            <material name="black"/>
        </visual>
    </link>

    <!--Right-back Wheel-->
    <joint name="right_back_wheel_joint" type="continuous">
        <parent link="base_link"/>
        <child link="right_back_wheel"/>
        <origin xyz="-0.047 -0.065 0" rpy="${pi/2} 0 0"/>
        <axis xyz="0 0 -1"/>
    </joint>

    <link name="right_back_wheel">
        <visual>
            <origin xyz="0 0 0" rpy="0 0 0"/>
            <geometry>
                <cylinder length="0.02" radius="0.0235"/>
            </geometry>
            <material name="black"/>
        </visual>
    </link>
</robot>